Workbook

Sheet Read Me
A1: OpenOKR user acceptance test
A2: A step-by-step test of the whole product through its screens, done by a person. It follows the order the product is used in: install, invite the team, plan the cycle, draft and publish OKRs, run the week, close the quarter, then the integrations.
A4: The workflow at a glance
A53: How to use this workbook
A54: 1 | B54: Start a fresh instance with an empty database and the staging overlay (docs/install/staging.md). Note the URL.
A55: 2 | B55: Type the shared inbox on the Personas sheet. The seven persona addresses fill themselves in.
A56: 3 | B56: Work down the Test Cases sheet in order. Each module builds on the one before it.
A57: 4 | B57: Sign in as the person in "Login as". Check the Pre-condition, follow the Steps, compare with Expected result.
A58: 5 | B58: Pick a Status from the dropdown. For anything other than Pass, write what you saw in "Actual result / notes".
A59: 6 | B59: For each Fail or Error, add a row on Bug Log with a screenshot link, and put its Bug ID on the test case.
A60: 7 | B60: Read the Summary sheet for the totals. It updates by itself.
A62: Status | B62: When to use it
A63: Not Run | B63: Not tested yet. Every case starts here.
A64: Pass | B64: What you saw matches Expected result.
A65: Fail | B65: The screen works but the result is different from Expected result. Wrong text, wrong number, missing item, a refusal that should not happen.
A66: Error | B66: The app broke: an error page, "We could not load", a blank screen, a spinner that never ends, or a crash.
A67: Blocked | B67: You could not run the test because something earlier failed, or a pre-condition cannot be met. Say which in the notes.
A68: N/A | B68: Does not apply to this instance, for example no Slack workspace or no passkey device.
A70: Before you start
A71: Browsers | B71: One browser profile per persona. Two screens help for M13 and M15, where two people act at once.
A72: Personas | B72: The seven accounts are created by a command after the setup wizard (M02-04), not by hand. They join through a real invitation, and titles, managers and spaces stay empty for M06 and M07.
A73: Email | B73: Every persona address is a plus-address on one inbox, so reset mails reach it once SMTP is set up. Without SMTP the instance prints every mail to its log, and invitation links are also shown once on Admin, Invitations. Mailpit is the quick fix (SMTP on port 1025, inbox at http://localhost:8025).
A74: Server access | B74: A few cases need someone who can read logs, restart the instance or run a pnpm command. They say so in the hint.
A75: AI | B75: AI is off by default and everything before M20 is tested with it off. M20 needs a provider key with a spending limit.
A76: Integrations | B76: M21 to M26 need outside accounts (Slack, Teams, WhatsApp, Telegram, an identity provider, an MCP client). Mark N/A for any you do not have.
A77: Never | B77: Paste an API key, a token or a real person's password into this workbook. The one shared password on Personas belongs to test accounts on the staging instance only.
A79: Known risks found while writing this
A80: Publishing | B80: Code review suggests gates 2 and 5 have no field in the UI. M11-05 tests it. If they cannot turn green, publish with the override in M11-07.
A81: Sessions | B81: Sessions cannot be created from the UI. The only weekly session is the one the starter template makes in M02. Quarterly reviews may not be reachable at all (M18-06).
A82: Admins | B82: Only the first account has full access, and no screen grants it to anyone else.
A83: Chat test | B83: "Send me a test" on Admin, Channels sends an email, not a chat message.
A84: 2FA | B84: There is no button to turn one-time codes off. Use the throwaway persona Amara.
A86: Generated from docs/testing/uat-cases.mjs and uat-guide.mjs. 193 test cases across 26 modules.

Sheet Module Guide
A1: Module guide
A2: What each module is for and how it flows, in the order to test it. The Test Cases sheet has the detailed steps; this sheet is the map.
A4: Module | B4: Phase | C4: What it proves | D4: Screens | E4: Who signs in | F4: Workflow | G4: Needs first | H4: Leaves ready for later | I4: Setup needed | J4: Time (min)
A5: M01 Install and first account | B5: 1. Set up | C5: Turn an empty server into an instance with one owner | D5: /setup, /setup/account, /sign-up | E5: Admin | F5: 1. Open the instance and get sent to setup 2. Name the instance Northwind Labs 3. Create the owner account 4. Check that registration is now closed | G5: Nothing. Start here | H5: An owner account. Everybody after this joins by invitation | I5: A fresh instance with an empty database | J5: 10
A6: M02 Welcome wizard | B6: 1. Set up | C6: Give the new workspace its name, clock, rhythm and starting content | D6: /welcome | E6: Admin | F6: 1. Name the workspace and pick its timezone 2. Choose the check-in rhythm 3. Skip the invite 4. Apply the OKR starter cycle template 5. Land on the work map 6. Operator runs deploy/staging/seed.sh for the seven personas 7. One persona signs in | G6: M01 | H6: A current cycle, one objective with 3 key results, a KPI, a KPI tree, the weekly session M15 needs, and seven persona accounts | I6: Someone with shell access to the staging host for the seed step | J6: 20
A7: M03 Workspace settings | B7: 1. Set up | C7: Check that workspace settings save, reload and reset | D7: Admin: General, Branding, Rhythm and thresholds | E7: Admin | F7: 1. Change timezone and language 2. Check the mail warning 3. Set a brand colour 4. Set the check-in rhythm 5. Rename a concept, then set it back | G7: M02 | H7: The rhythm every later reminder and due date follows | I7: Nothing extra | J7: 15
A8: M04 Invitations | B8: 2. Build the team | C8: Check the invitation path with spare people, since the personas were seeded | D8: Admin, Invitations; /join/<token>; /sign-up | E8: Admin, then spare addresses | F8: 1. Admin invites +leaver personally 2. Test Leaver opens the link and signs up 3. A wrong address is refused 4. A shared link admits +guest1 and +guest2 5. A domain outside the list is refused 6. Revoked and made-up links are refused | G8: M02 | H8: Test Leaver, the spare account M19 erases | I8: The shared inbox and a private browser window | J8: 15
A9: M05 Sign-in and account security | B9: 2. Build the team | C9: Prove sign-in, password reset and the second factor protect an account | D9: /sign-in, /forgot-password, /reset-password, /backup-code, Account, Security | E9: Jonas, Mei, Amara, Sara, Priya | F9: 1. Refuse a wrong password 2. Reset a forgotten password by mail 3. Turn on one-time codes for Amara 4. Sign in with a code and with a backup code 5. Add a passkey 6. Revoke another device | G9: M02 | H9: Confidence that accounts are safe before real data goes in | I9: Mailpit or SMTP for the reset mail. An authenticator app | J9: 30
A10: M06 People and org chart | B10: 2. Build the team | C10: Give everyone a title and a manager so the org chart is real | D10: People, People / <person> | E10: Admin, Mei, Jonas, Tomas | F10: 1. Admin sets title and manager for each persona 2. Check the org chart 3. A loop in the chain is refused 4. Members edit only their own profile 5. Suspend and restore Tomas | G10: M02 | H10: Reporting lines, used by the org chart and by who reviews whom | I10: Nothing extra | J10: 20
A11: M07 Spaces | B11: 2. Build the team | C11: Create the team homes that own goals, boards and sessions | D11: Spaces, Spaces / <space> | E11: Admin, Priya, Amara, Jonas | F11: 1. Admin creates Product, Sales and Customer Success 2. Priya adds members with roles 3. A member joins and leaves 4. A non-manager cannot manage 5. Change settings, archive a spare space | G11: M06 | H11: Spaces that goals, the board and the weekly session belong to | I11: Nothing extra | J11: 20
A12: M08 Cycle: prepare, diagnose, direction | B12: 3. Plan the cycle | C12: Walk the first three phases so drafting has something to stand on | D12: Cycle (phases 1 to 3), Cycles card | E12: Admin, Priya | F12: 1. Read the eight-phase rail 2. Create the next cycle and set the publication deadline 3. Phase 1: sponsor, facilitator, input pack 4. Phase 2: rank three strategic issues 5. Phase 3: choose a priority | G12: M07 | H12: A priority for objectives to contribute to, and the deadline gate 6 checks | I12: Nothing extra | J12: 25
A13: M09 Drafting OKRs and quality checks | B13: 3. Plan the cycle | C13: Draft objectives and key results while the quality checks fire live | D13: Cycle, phase 4; /method/<rule> | E13: Sara, Daniel, Tomas | F13: 1. Draft Sara's objective with champion and reviewer 2. Type weak wording and watch OBJ-1 and OBJ-2 fire 3. Open a rule card and the method page 4. Add key results, weak then measurable 5. Record a current value 6. Daniel and Tomas draft their own | G13: M08 | H13: A draft set of objectives for three teams | I13: AI off | J13: 40
A14: M10 Goal page and documents | B14: 3. Plan the cycle | C14: Work on one goal: values, confidence, comments, documents and files | D14: Goals, Goals / <goal>, Documents / <doc> | E14: Sara, Priya, Mei, Jonas | F14: 1. Open the goal and read its header 2. Update values and confidence 3. Comment and watch 4. Start a private document, then publish two versions 5. Attach and detach a file 6. Filter the explorer | G14: M09 | H14: A goal with history, discussion and a document | I14: A small PDF to attach | J14: 30
A15: M11 Alignment and publishing | B15: 3. Plan the cycle | C15: Align the set and publish it through the six gates | D15: Goals, Alignment studio; Cycle, phase 5 | E15: Priya, Admin | F15: 1. Look at the cascade 2. Link a team goal to the company goal 3. Record and confirm a dependency 4. Read each gate and follow its fix 5. Publish, or override with a reason 6. Check a member cannot publish | G15: M10 | H15: A published set. The cycle moves to phase 6 and check-ins start | I15: Nothing extra | J15: 30
A16: M12 KPIs and recovery | B16: 4. Run the cycle | C16: Track KPIs continuously and recover one that falls out of its corridor | D16: KPIs grid, KPIs / <kpi>, Trees, Recovery board | E16: Priya, Admin | F16: 1. Add a KPI 2. Enter values and watch green, amber and red 3. Build a formula and a tree 4. Let a KPI drop to red 5. Launch a recovery objective 6. Move a threshold and see colours change | G16: M11 | H16: A recovering KPI with its own objective | I16: Nothing extra | J16: 30
... A30: M26 Cloud operator console | B30: 6. Integrations | C30: Check the managed-cloud operator console | D30: /operator, /operator/<workspace>, /operator/instance, Admin, Support access | E30: Operator, Admin, Sara | F30: 1. Console is hidden on self-hosted 2. Operator lists workspaces 3. Suspend and restore a workspace 4. Ask for and approve support access 5. Show an instance banner | G30: M04 | H30: Cloud operations checked | I30: OPENOKR_CLOUD=true and an operator granted with pnpm cloud:operator | J30: 30
A31: Total time | J31: =SUM(J5:J30)

Sheet Summary
A1: Test summary
A2: Every number below is a formula over the Test Cases sheet. Set the Status column there and this page updates.
A4: Module | B4: Cases | C4: Pass | D4: Fail | E4: Error | F4: Blocked | G4: N/A | H4: Not run | I4: Executed | J4: Pass rate
A5: M01 Install and first account | B5: =COUNTIF('Test Cases'!$B:$B,$A5) | C5: =COUNTIFS('Test Cases'!$B:$B,$A5,'Test Cases'!$J:$J,"Pass") | D5: =COUNTIFS('Test Cases'!$B:$B,$A5,'Test Cases'!$J:$J,"Fail") | E5: =COUNTIFS('Test Cases'!$B:$B,$A5,'Test Cases'!$J:$J,"Error") | F5: =COUNTIFS('Test Cases'!$B:$B,$A5,'Test Cases'!$J:$J,"Blocked") | G5: =COUNTIFS('Test Cases'!$B:$B,$A5,'Test Cases'!$J:$J,"N/A") | H5: =B5-SUM(C5:G5) | I5: =C5+D5+E5 | J5: =IF(I5=0,"",C5/I5)
A6: M02 Welcome wizard | B6: =COUNTIF('Test Cases'!$B:$B,$A6) | C6: =COUNTIFS('Test Cases'!$B:$B,$A6,'Test Cases'!$J:$J,"Pass") | D6: =COUNTIFS('Test Cases'!$B:$B,$A6,'Test Cases'!$J:$J,"Fail") | E6: =COUNTIFS('Test Cases'!$B:$B,$A6,'Test Cases'!$J:$J,"Error") | F6: =COUNTIFS('Test Cases'!$B:$B,$A6,'Test Cases'!$J:$J,"Blocked") | G6: =COUNTIFS('Test Cases'!$B:$B,$A6,'Test Cases'!$J:$J,"N/A") | H6: =B6-SUM(C6:G6) | I6: =C6+D6+E6 | J6: =IF(I6=0,"",C6/I6)
A7: M03 Workspace settings | B7: =COUNTIF('Test Cases'!$B:$B,$A7) | C7: =COUNTIFS('Test Cases'!$B:$B,$A7,'Test Cases'!$J:$J,"Pass") | D7: =COUNTIFS('Test Cases'!$B:$B,$A7,'Test Cases'!$J:$J,"Fail") | E7: =COUNTIFS('Test Cases'!$B:$B,$A7,'Test Cases'!$J:$J,"Error") | F7: =COUNTIFS('Test Cases'!$B:$B,$A7,'Test Cases'!$J:$J,"Blocked") | G7: =COUNTIFS('Test Cases'!$B:$B,$A7,'Test Cases'!$J:$J,"N/A") | H7: =B7-SUM(C7:G7) | I7: =C7+D7+E7 | J7: =IF(I7=0,"",C7/I7)
A8: M04 Invitations | B8: =COUNTIF('Test Cases'!$B:$B,$A8) | C8: =COUNTIFS('Test Cases'!$B:$B,$A8,'Test Cases'!$J:$J,"Pass") | D8: =COUNTIFS('Test Cases'!$B:$B,$A8,'Test Cases'!$J:$J,"Fail") | E8: =COUNTIFS('Test Cases'!$B:$B,$A8,'Test Cases'!$J:$J,"Error") | F8: =COUNTIFS('Test Cases'!$B:$B,$A8,'Test Cases'!$J:$J,"Blocked") | G8: =COUNTIFS('Test Cases'!$B:$B,$A8,'Test Cases'!$J:$J,"N/A") | H8: =B8-SUM(C8:G8) | I8: =C8+D8+E8 | J8: =IF(I8=0,"",C8/I8)
A9: M05 Sign-in and account security | B9: =COUNTIF('Test Cases'!$B:$B,$A9) | C9: =COUNTIFS('Test Cases'!$B:$B,$A9,'Test Cases'!$J:$J,"Pass") | D9: =COUNTIFS('Test Cases'!$B:$B,$A9,'Test Cases'!$J:$J,"Fail") | E9: =COUNTIFS('Test Cases'!$B:$B,$A9,'Test Cases'!$J:$J,"Error") | F9: =COUNTIFS('Test Cases'!$B:$B,$A9,'Test Cases'!$J:$J,"Blocked") | G9: =COUNTIFS('Test Cases'!$B:$B,$A9,'Test Cases'!$J:$J,"N/A") | H9: =B9-SUM(C9:G9) | I9: =C9+D9+E9 | J9: =IF(I9=0,"",C9/I9)
A10: M06 People and org chart | B10: =COUNTIF('Test Cases'!$B:$B,$A10) | C10: =COUNTIFS('Test Cases'!$B:$B,$A10,'Test Cases'!$J:$J,"Pass") | D10: =COUNTIFS('Test Cases'!$B:$B,$A10,'Test Cases'!$J:$J,"Fail") | E10: =COUNTIFS('Test Cases'!$B:$B,$A10,'Test Cases'!$J:$J,"Error") | F10: =COUNTIFS('Test Cases'!$B:$B,$A10,'Test Cases'!$J:$J,"Blocked") | G10: =COUNTIFS('Test Cases'!$B:$B,$A10,'Test Cases'!$J:$J,"N/A") | H10: =B10-SUM(C10:G10) | I10: =C10+D10+E10 | J10: =IF(I10=0,"",C10/I10)
A11: M07 Spaces | B11: =COUNTIF('Test Cases'!$B:$B,$A11) | C11: =COUNTIFS('Test Cases'!$B:$B,$A11,'Test Cases'!$J:$J,"Pass") | D11: =COUNTIFS('Test Cases'!$B:$B,$A11,'Test Cases'!$J:$J,"Fail") | E11: =COUNTIFS('Test Cases'!$B:$B,$A11,'Test Cases'!$J:$J,"Error") | F11: =COUNTIFS('Test Cases'!$B:$B,$A11,'Test Cases'!$J:$J,"Blocked") | G11: =COUNTIFS('Test Cases'!$B:$B,$A11,'Test Cases'!$J:$J,"N/A") | H11: =B11-SUM(C11:G11) | I11: =C11+D11+E11 | J11: =IF(I11=0,"",C11/I11)
A12: M08 Cycle: prepare, diagnose, direction | B12: =COUNTIF('Test Cases'!$B:$B,$A12) | C12: =COUNTIFS('Test Cases'!$B:$B,$A12,'Test Cases'!$J:$J,"Pass") | D12: =COUNTIFS('Test Cases'!$B:$B,$A12,'Test Cases'!$J:$J,"Fail") | E12: =COUNTIFS('Test Cases'!$B:$B,$A12,'Test Cases'!$J:$J,"Error") | F12: =COUNTIFS('Test Cases'!$B:$B,$A12,'Test Cases'!$J:$J,"Blocked") | G12: =COUNTIFS('Test Cases'!$B:$B,$A12,'Test Cases'!$J:$J,"N/A") | H12: =B12-SUM(C12:G12) | I12: =C12+D12+E12 | J12: =IF(I12=0,"",C12/I12)
A13: M09 Drafting OKRs and quality checks | B13: =COUNTIF('Test Cases'!$B:$B,$A13) | C13: =COUNTIFS('Test Cases'!$B:$B,$A13,'Test Cases'!$J:$J,"Pass") | D13: =COUNTIFS('Test Cases'!$B:$B,$A13,'Test Cases'!$J:$J,"Fail") | E13: =COUNTIFS('Test Cases'!$B:$B,$A13,'Test Cases'!$J:$J,"Error") | F13: =COUNTIFS('Test Cases'!$B:$B,$A13,'Test Cases'!$J:$J,"Blocked") | G13: =COUNTIFS('Test Cases'!$B:$B,$A13,'Test Cases'!$J:$J,"N/A") | H13: =B13-SUM(C13:G13) | I13: =C13+D13+E13 | J13: =IF(I13=0,"",C13/I13)
A14: M10 Goal page and documents | B14: =COUNTIF('Test Cases'!$B:$B,$A14) | C14: =COUNTIFS('Test Cases'!$B:$B,$A14,'Test Cases'!$J:$J,"Pass") | D14: =COUNTIFS('Test Cases'!$B:$B,$A14,'Test Cases'!$J:$J,"Fail") | E14: =COUNTIFS('Test Cases'!$B:$B,$A14,'Test Cases'!$J:$J,"Error") | F14: =COUNTIFS('Test Cases'!$B:$B,$A14,'Test Cases'!$J:$J,"Blocked") | G14: =COUNTIFS('Test Cases'!$B:$B,$A14,'Test Cases'!$J:$J,"N/A") | H14: =B14-SUM(C14:G14) | I14: =C14+D14+E14 | J14: =IF(I14=0,"",C14/I14)
A15: M11 Alignment and publishing | B15: =COUNTIF('Test Cases'!$B:$B,$A15) | C15: =COUNTIFS('Test Cases'!$B:$B,$A15,'Test Cases'!$J:$J,"Pass") | D15: =COUNTIFS('Test Cases'!$B:$B,$A15,'Test Cases'!$J:$J,"Fail") | E15: =COUNTIFS('Test Cases'!$B:$B,$A15,'Test Cases'!$J:$J,"Error") | F15: =COUNTIFS('Test Cases'!$B:$B,$A15,'Test Cases'!$J:$J,"Blocked") | G15: =COUNTIFS('Test Cases'!$B:$B,$A15,'Test Cases'!$J:$J,"N/A") | H15: =B15-SUM(C15:G15) | I15: =C15+D15+E15 | J15: =IF(I15=0,"",C15/I15)
A16: M12 KPIs and recovery | B16: =COUNTIF('Test Cases'!$B:$B,$A16) | C16: =COUNTIFS('Test Cases'!$B:$B,$A16,'Test Cases'!$J:$J,"Pass") | D16: =COUNTIFS('Test Cases'!$B:$B,$A16,'Test Cases'!$J:$J,"Fail") | E16: =COUNTIFS('Test Cases'!$B:$B,$A16,'Test Cases'!$J:$J,"Error") | F16: =COUNTIFS('Test Cases'!$B:$B,$A16,'Test Cases'!$J:$J,"Blocked") | G16: =COUNTIFS('Test Cases'!$B:$B,$A16,'Test Cases'!$J:$J,"N/A") | H16: =B16-SUM(C16:G16) | I16: =C16+D16+E16 | J16: =IF(I16=0,"",C16/I16)
... A30: M26 Cloud operator console | B30: =COUNTIF('Test Cases'!$B:$B,$A30) | C30: =COUNTIFS('Test Cases'!$B:$B,$A30,'Test Cases'!$J:$J,"Pass") | D30: =COUNTIFS('Test Cases'!$B:$B,$A30,'Test Cases'!$J:$J,"Fail") | E30: =COUNTIFS('Test Cases'!$B:$B,$A30,'Test Cases'!$J:$J,"Error") | F30: =COUNTIFS('Test Cases'!$B:$B,$A30,'Test Cases'!$J:$J,"Blocked") | G30: =COUNTIFS('Test Cases'!$B:$B,$A30,'Test Cases'!$J:$J,"N/A") | H30: =B30-SUM(C30:G30) | I30: =C30+D30+E30 | J30: =IF(I30=0,"",C30/I30)
A31: Total | B31: =SUM(B5:B30) | C31: =SUM(C5:C30) | D31: =SUM(D5:D30) | E31: =SUM(E5:E30) | F31: =SUM(F5:F30) | G31: =SUM(G5:G30) | H31: =SUM(H5:H30) | I31: =SUM(I5:I30) | J31: =IF(I31=0,"",C31/I31)
A33: Executed counts Pass, Fail and Error. Pass rate is Pass divided by Executed. Blocked and N/A are left out of the rate because nothing was judged. A blank Status counts as Not run.

Sheet Personas
A1: Personas
A2: The Northwind Labs cast from the product's own demo story. Every test case names who to sign in as. Type the shared inbox in the yellow cell below: the seven addresses fill themselves in, and sh deploy/staging/seed.sh --inbox <that inbox> creates exactly those accounts (M02-04).
A4: Shared inbox | C4: For example qa.okr@gmail.com. No plus sign: each persona adds its own.
A5: Shared password | B5: northwind-uat-2026 | C5: The seed command's default. Change it here if the command was run with --password.
A7: Persona | B7: Full name | C7: Title | D7: Reports to | E7: Sign-in email | F7: Password | G7: Access and role in the test | H7: Used in
A8: Admin | B8: (your own name) | C8: Chief Executive | D8: Nobody | G8: Full access. The first account. The only one who can open Admin screens | H8: All
A9: Priya | B9: Priya Raman | C9: Chief Product Officer | D9: Admin | E9: =IF($B$4="","",LOWER(SUBSTITUTE($B$4,"@","+priya@"))) | F9: =$B$5 | G9: Member (edit). Manager of the Product space. Reviewer of Sara's goal | H9: M02, M06, M07, M11, M14, M15
A10: Daniel | B10: Daniel Osei | C10: VP Sales | D10: Admin | E10: =IF($B$4="","",LOWER(SUBSTITUTE($B$4,"@","+daniel@"))) | F10: =$B$5 | G10: Member (edit). Manager of the Sales space. Champion of the sales objective | H10: M06, M07, M09
A11: Tomas | B11: Tomás Herrera | C11: Head of Customer Success | D11: Admin | E11: =IF($B$4="","",LOWER(SUBSTITUTE($B$4,"@","+tomas@"))) | F11: =$B$5 | G11: Member (edit). Manager of the Customer Success space. Used for suspend and restore | H11: M06, M07, M09
A12: Mei | B12: Mei Lin | C12: Head of Engineering | D12: Priya | E12: =IF($B$4="","",LOWER(SUBSTITUTE($B$4,"@","+mei@"))) | F12: =$B$5 | G12: Member (edit). Owns initiatives. Used as the wrong reviewer | H12: M05, M06, M13, M14
A13: Sara | B13: Sara Nasser | C13: Product Manager, Onboarding | D13: Priya | E13: =IF($B$4="","",LOWER(SUBSTITUTE($B$4,"@","+sara@"))) | F13: =$B$5 | G13: Member (edit). Champion of the onboarding objective. Does the check-ins | H13: M09, M14, M15
A14: Jonas | B14: Jonas Weber | C14: Account Executive | D14: Daniel | E14: =IF($B$4="","",LOWER(SUBSTITUTE($B$4,"@","+jonas@"))) | F14: =$B$5 | G14: Member (edit). Used for the 'cannot do this' checks | H14: M05, M06, M07, M14, M19
A15: Amara | B15: Amara Diallo | C15: Data Analyst | D15: Admin | E15: =IF($B$4="","",LOWER(SUBSTITUTE($B$4,"@","+amara@"))) | F15: =$B$5 | G15: Member (edit). Throwaway account for 2FA and guest tests | H15: M05, M19
A17: Spare addresses for M04 and M19 use the same inbox: +leaver, +wrong, +other, +guest1, +guest2. Use one browser profile per persona (Chrome profiles, Firefox containers or separate browsers); it lets two people act at once in M13 and M15.

Sheet Test Cases
A1: ID | B1: Module | C1: Test case | D1: Login as | E1: Pre-condition | F1: Steps | G1: Expected result | H1: Priority | I1: Hint for the tester | J1: Status | K1: Actual result / notes | L1: Tester | M1: Date | N1: Bug ID
A2: M01 Install and first account: Turn an empty server into an instance with one owner. About 10 min. Full workflow on the Module Guide sheet.
A3: M01-01 | B3: M01 Install and first account | C3: An empty instance sends every visitor to setup | D3: Nobody (signed out) | E3: Fresh instance, empty database, no account yet | F3: 1. Open the instance URL followed by /sign-in | G3: Redirected to /setup. Heading "Set up OpenOKR". The "This deployment" section lists the connection checks. Button "Create the first account" is shown | H3: High | J3: Not Run
A4: M01-02 | B4: M01 Install and first account | C4: A short password is refused on the first account | D4: Admin | E4: M01-01 done | F4: 1. Click "Create the first account" 2. Fill "Your name" and "Email" 3. Type an 8-character password 4. Click "Finish setup" | G4: The form refuses the password and points at the 12-character minimum. No account is created | H4: Medium | J4: Not Run
A5: M01-03 | B5: M01 Install and first account | C5: Create the first account | D5: Admin | E5: M01-02 done | F5: 1. Set "What should this instance be called?" to Northwind Labs 2. Fill your own name, your email and a password of 12 or more characters 3. Click "Finish setup" | G5: Button reads "Setting up..." then you land on /welcome with heading "Set up your workspace" | H5: High | I5: Write down the email and password. This is the only full-access account for the whole test | J5: Not Run
A6: M01-04 | B6: M01 Install and first account | C6: Registration closes once the first account exists | D6: Nobody (signed out) | E6: M01-03 done. Use a private browser window | F6: 1. Open /sign-up 2. Open /setup | G6: /sign-up shows "Registration is closed" with "Back to sign in". /setup shows "Setup is already done" with "Go to the instance" | H6: High | J6: Not Run
A7: M02 Welcome wizard: Give the new workspace its name, clock, rhythm and starting content. Needs M01 first. About 20 min. Full workflow on the Module Guide sheet.
A8: M02-01 | B8: M02 Welcome wizard | C8: Walk the welcome wizard with the starter template | D8: Admin | E8: Signed in right after M01-03 | F8: 1. Workspace name: Northwind Labs. Click "Continue" 2. Pick your timezone. Check-in frequency: "Weekly". Click "Continue" 3. Invite step: click "Skip" 4. Template step: choose "OKR starter cycle" and click "Use this template" 5. Worked example step: click "Start empty" | G8: The wizard closes and the work map opens. It shows the objective "Make onboarding the reason new customers stay" with 3 key results | H8: High | I8: Skip the invite here. An invite sent from the wizard never shows its link on screen. M04 invites everybody from Admin, Invitations instead | J8: Not Run
A9: M02-02 | B9: M02 Welcome wizard | C9: The template created its KPI, space content and session | D9: Admin | E9: M02-01 done | F9: 1. Open KPIs 2. Open KPIs, Trees 3. Open Sessions | G9: KPIs shows "30-day retention" under category Customer. Trees shows a tree named Retention. Sessions shows "Weekly session" under "Ahead" with the chip "You facilitate" | H9: High | I9: This weekly session is the only one M15 can use. The UI has no way to create another | J9: Not Run
A10: M02-03 | B10: M02 Welcome wizard | C10: The wizard does not come back | D10: Admin | E10: M02-01 done | F10: 1. Sign out and sign in again 2. Open /welcome directly | G10: Sign-in lands on the work map. /welcome redirects to / | H10: Medium | J10: Not Run
A11: M02-04 | B11: M02 Welcome wizard | C11: Create the seven persona accounts | D11: Admin (server access) | E11: M02-01 done. The stack runs with deploy/staging/compose.staging.yaml | F11: 1. On the staging host run: sh deploy/staging/seed.sh --inbox <the inbox on Personas> 2. Read the list it prints 3. Open People 4. Open Admin, Invitations | G11: The command prints seven addresses and the password. People lists all seven with no title and no manager. Invitations shows one workspace link, 7 uses, status "Revoked" | H11: High | I11: Run it once. A second run changes nothing. It refuses a workspace that already has other people in it | J11: Not Run
A12: M02-05 | B12: M02 Welcome wizard | C12: A persona can sign in | D12: Priya | E12: M02-04 done. A private window | F12: 1. Sign in with Priya's address from Personas and the shared password | G12: Priya lands on the work map of Northwind Labs, not on the welcome wizard | H12: High | J12: Not Run
A13: M03 Workspace settings: Check that workspace settings save, reload and reset. Needs M02 first. About 15 min. Full workflow on the Module Guide sheet.
A14: M03-01 | B14: M03 Workspace settings | C14: Save and reload general settings | D14: Admin | E14: Signed in | F14: 1. Open Admin, General 2. Set "Timezone" and "Language" 3. Click "Save" 4. Reload the page | G14: The values you saved are still there after the reload | H14: High | J14: Not Run
A15: M03-02 | B15: M03 Workspace settings | C15: The console mail warning is visible | D15: Admin | E15: Instance has no SMTP settings | F15: 1. Open Admin, General | G15: A banner says "Every message is going to the log, not to anybody" | H15: Medium | I15: If SMTP or Mailpit is already set up, mark N/A | J15: Not Run
A16: M03-03 | B16: M03 Workspace settings | C16: Reset general settings to defaults | D16: Admin | E16: M03-01 done | F16: 1. Change a value 2. Click "Reset to defaults" 3. Confirm | G16: Every field returns to its default value | H16: Low | J16: Not Run
A17: M03-04 | B17: M03 Workspace settings | C17: Brand colour applies across the app | D17: Admin | E17: Signed in | F17: 1. Open Admin, Branding 2. Type #336699 in "Primary colour (hex)" 3. Click "Save" 4. Open the work map 5. Try the value blue and save | G17: The primary colour changes on buttons and links. The value blue is refused with a message. Write the message in Actual result | H17: Low | J17: Not Run
A18: M03-05 | B18: M03 Workspace settings | C18: Rhythm settings show the value in force | D18: Admin | E18: Signed in | F18: 1. Open Admin, Rhythm and thresholds 2. Look at each group card 3. Set "Check-in frequency" to weekly and "Anchor day" to Monday 4. Click "Save" | G18: Every field shows "in force: <value>". After saving, the new values show as in force | H18: High | J18: Not Run
A19: M03-06 | B19: M03 Workspace settings | C19: Rename a concept in Terminology | D19: Admin | E19: Signed in | F19: 1. Open Admin, Rhythm and thresholds, Terminology 2. Rename Objective to Goal (singular and plural) 3. Save and open the work map 4. Set it back afterwards | G19: Screens use the new word. After setting it back, the old word returns | H19: Low | J19: Not Run
A20: M04 Invitations: Check the invitation path with spare people, since the personas were seeded. Needs M02 first. About 15 min. Full workflow on the Module Guide sheet.
A21: M04-01 | B21: M04 Invitations | C21: Send a personal invitation | D21: Admin | E21: M02-04 done. Spare address: the inbox from Personas with +leaver | F21: 1. Open Admin, Invitations 2. In "Invite one person" type the +leaver address 3. Keep "Expires in days" at 14 4. Click "Create the invitation" | G21: A box says "Copy this now. It is not shown again." and shows the link. The "Issued" card lists the row with status "Open" | H21: High | I21: Copy the link into a notepad. With SMTP set up the mail also arrives in the shared inbox | J21: Not Run
A22: M04-02 | B22: M04 Invitations | C22: Accept an invitation as a new person | D22: Test Leaver (spare) | E22: M04-01 done. Use a private window | F22: 1. Open the invitation link 2. Click "Create an account" 3. Sign up with the +leaver address, name Test Leaver, and a 12+ character password | G22: The join page says "You have been invited to Northwind Labs". After sign-up Test Leaver is inside the workspace. On Admin, Invitations the row now shows "Used up" | H22: High | I22: Keep this account. M19-05 erases it | J22: Not Run
A23: M04-03 | B23: M04 Invitations | C23: An invitation refuses a different email address | D23: Nobody (signed out) | E23: Admin created a personal invitation for the +wrong address | F23: 1. Open that link in a private window 2. Click "Create an account" 3. Sign up with the +other address instead | G23: The page warns "This invitation was issued to a different address, so it will be refused" and joining is refused | H23: High | J23: Not Run
A24: M04-04 | B24: M04 Invitations | C24: Invite people with a shared link | D24: Admin | E24: Signed in | F24: 1. In "Create a link to share" set "Maximum uses" to 2 and "Allowed domains" to the inbox's domain 2. Click "Create the link" 3. Open the link twice in separate private windows and sign up as +guest1 and +guest2 | G24: Both join. The row shows 2 uses and then "Used up" | H24: High | I24: The seven personas were not invited this way, so their sign-in is tested in M05, not here | J24: Not Run
A25: M04-05 | B25: M04 Invitations | C25: A shared link refuses a domain outside the list | D25: Nobody (signed out) | E25: M04-04 link still has uses left, or create a new one | F25: 1. Open the link 2. Sign up with an email from another domain | G25: Joining is refused. No new member appears in People | H25: Medium | J25: Not Run
A26: M04-06 | B26: M04 Invitations | C26: Revoke an invitation | D26: Admin | E26: Signed in | F26: 1. Create a personal invitation for a spare email 2. Click "Revoke" on its row and confirm 3. Open the revoked link in a private window | G26: The row shows "Revoked". The link page says "That invitation cannot be used" with "Sign in instead" | H26: High | J26: Not Run
A27: M04-07 | B27: M04 Invitations | C27: A made-up invitation link is refused | D27: Nobody (signed out) | E27: None | F27: 1. Open /join/abc123 | G27: "That invitation cannot be used" | H27: Low | J27: Not Run
A28: M05 Sign-in and account security: Prove sign-in, password reset and the second factor protect an account. Needs M02 first. About 30 min. Full workflow on the Module Guide sheet.
A29: M05-01 | B29: M05 Sign-in and account security | C29: Wrong password is refused | D29: Jonas | E29: Signed out | F29: 1. Open /sign-in 2. Type Jonas's email and a wrong password 3. Click "Sign in" | G29: "Those details did not match. Check them and try again." | H29: High | J29: Not Run
A30: M05-02 | B30: M05 Sign-in and account security | C30: Sign in and sign out | D30: Jonas | E30: Signed out | F30: 1. Sign in with the right password 2. Sign out | G30: Sign-in lands on the work map. Sign-out returns to the sign-in page. Pressing Back does not show workspace data | H30: High | J30: Not Run
A31: M05-03 | B31: M05 Sign-in and account security | C31: Reset a forgotten password | D31: Mei | E31: Signed out. SMTP or Mailpit set up, and access to the shared inbox | F31: 1. Click "Forgot your password?" 2. Type Mei's email and click "Send reset link" 3. Open the reset link from the mail 4. Type a new password in "New password" and click "Set password" 5. Sign in with the new password | G31: "Check your email" appears. The link opens "Choose a new password". Sign-in works with the new password and not with the old one | H31: High | I31: The mail goes to the +mei plus-address, so it lands in the shared inbox. Without SMTP it is only in the server log | J31: Not Run
A32: M05-04 | B32: M05 Sign-in and account security | C32: A used reset link cannot be used again | D32: Mei | E32: M05-03 done | F32: 1. Open the same reset link again 2. Try to set a password | G32: "That link has expired or was already used. Ask for a new one." | H32: Medium | J32: Not Run
A33: M05-05 | B33: M05 Sign-in and account security | C33: Turn on one-time codes (2FA) | D33: Amara | E33: Signed in. An authenticator app that accepts a pasted otpauth link (Google Authenticator, 1Password, Authy) | F33: 1. Open Account, Security 2. Type the password in "Confirm your password" and click "Set up one-time codes" 3. Add the shown otpauth text to the authenticator app 4. Save the backup codes somewhere 5. Type the code in "Code from your app" and click "Turn on" | G33: 2FA is on. The backup codes were shown once | H33: High | I33: The screen shows text, not a QR code. There is no button to turn 2FA off again, so use Amara only | J33: Not Run
A34: M05-06 | B34: M05 Sign-in and account security | C34: Sign in with a one-time code | D34: Amara | E34: M05-05 done. Signed out | F34: 1. Sign in with email and password 2. On "Enter your code" type a wrong code and click "Verify" 3. Type the right code and click "Verify" | G34: Wrong code: "That code was not right. Codes change every 30 seconds." Right code: signed in | H34: High | J34: Not Run
A35: M05-07 | B35: M05 Sign-in and account security | C35: Sign in with a backup code, once only | D35: Amara | E35: M05-05 done. Signed out | F35: 1. Sign in with email and password 2. Open the "backup code page" link 3. Enter one backup code and click "Verify" 4. Sign out and try the same backup code again | G35: First use signs in. Second use: "That backup code was not recognised, or it has been used." | H35: Medium | J35: Not Run
A36: M05-08 | B36: M05 Sign-in and account security | C36: Add a passkey and sign in with it | D36: Sara | E36: A device with Windows Hello, Touch ID or a security key | F36: 1. Open Account, Security, click "Add a passkey" 2. Sign out 3. Click "Sign in with a passkey" | G36: The passkey is listed. Sign-in with it works without a password | H36: Low | I36: Mark N/A if the device has no passkey support | J36: Not Run
A37: M05-09 | B37: M05 Sign-in and account security | C37: Revoke another signed-in device | D37: Priya | E37: Priya signed in on two browsers | F37: 1. In browser 1 open Account, Security, Sessions 2. Click "Revoke" on the other device 3. Reload browser 2 | G37: Browser 2 is signed out | H37: Medium | J37: Not Run
A38: M05-10 | B38: M05 Sign-in and account security | C38: Too many sign-in attempts are slowed down | D38: Jonas | E38: Signed out | F38: 1. Try a wrong password about 10 times quickly | G38: "Too many attempts. Wait a minute and try again." | H38: Low | J38: Not Run
A39: M06 People and org chart: Give everyone a title and a manager so the org chart is real. Needs M02 first. About 20 min. Full workflow on the Module Guide sheet.
A40: M06-01 | B40: M06 People and org chart | C40: Set titles and managers for the cast | D40: Admin | E40: All 7 personas joined | F40: 1. Open People, click each persona 2. In "Edit member (admin)" set "Title" and "Manager" from the Personas sheet 3. Click "Save" for each | G40: Each profile shows the title and manager you set | H40: High | J40: Not Run
...

Sheet Bug Log
A1: Bug ID | B1: Test ID | C1: Module | D1: Title | E1: Severity | F1: Steps to reproduce | G1: Expected | H1: Actual | I1: Screenshot or video link | J1: Browser and device | K1: Reported by | L1: Date | M1: Status
A2: BUG-001 | B2: M09-03 | C2: M09 Drafting OKRs and quality checks | D2: Example row, replace it: OBJ-1 chip missing | E2: Major | F2: 1. Open Cycle, phase 4 2. Type Launch the new onboarding flow | G2: OBJ-1 chip shows | H2: No chip, meter stays green | I2: https://link-to-screenshot | J2: Chrome 140, Windows 11 | K2: Tester name | L2: 2026-09-25 | M2: Open
